Workbook

Sheet OCD
A1: OCD - IOCC | B1: BẢNG PHÂN CÔNG LỊCH LÀM VIỆC | AI1: FORM: SPA-IOCC
AI2: Issue: 00
AI3: Revision: 00
AI4: Date: 03/09/2025
A7: Công kế hoạch | B7: 26
A8: Tháng 08/2026 | B8: =B7*8 -> 208
A10: Vị trí trực | B10: Mã nhân viên | C10: Họ tên | D10: 26 | E10: 27 | F10: 28 | G10: 29 | H10: 30 | I10: 31 | J10: 1 | K10: 2 | L10: 3 | M10: 4 | N10: 5 | O10: 6 | P10: 7 | Q10: 8 | R10: 9 | S10: 10 | T10: 11 | U10: 12 | V10: 13 | W10: 14 | X10: 15 | Y10: 16 | Z10: 17 | AA10: 18 | AB10: 19 | AC10: 20 | AD10: 21 | AE10: 22 | AF10: 23 | AG10: 24 | AH10: 25 | AI10: Tổng ca trực | AM10: Ca khác (8h) | AN10: Tổng giờ công | AO10: Note
D11: C.Nhật | E11: T.Hai | F11: T.Ba | G11: T.Tư | H11: T.Năm | I11: T.Sáu | J11: T.Bảy | K11: C.Nhật | L11: T.Hai | M11: T.Ba | N11: T.Tư | O11: T.Năm | P11: T.Sáu | Q11: T.Bảy | R11: C.Nhật | S11: T.Hai | T11: T.Ba | U11: T.Tư | V11: T.Năm | W11: T.Sáu | X11: T.Bảy | Y11: C.Nhật | Z11: T.Hai | AA11: T.Ba | AB11: T.Tư | AC11: T.Năm | AD11: T.Sáu | AE11: T.Bảy | AF11: C.Nhật | AG11: T.Hai | AH11: T.Ba | AI11: Ca HC | AJ11: Ca M | AK11: Ca E | AL11: Ca 9h-21h | AM11: NL: Nghỉ lễ P: Phép, B: Bù, SN, T: Training
A12: Duty Manager | B12: 030346 | C12: Đàm Xuân Hiến | D12: M | E12: E | H12: M | I12: M | J12: E | M12: M | N12: M | O12: E | S12: M | T12: E | W12: E | Y12: M | Z12: HC | AB12: HC | AC12: E | AE12: E | AG12: HC | AH12: E | AI12: =COUNTIF(D12:AH12,"HC") -> 3 | AJ12: =COUNTIF(D12:AH12,"M") -> 7 | AK12: =COUNTIF(D12:AH12,"E") -> 8 | AM12: {=SUM(COUNTIF(D12:AH12,{"NL","P","B","T","SN"}))} -> 0 | AN12: =AI12*8+AJ12*12+AK12*12+AM12*8 -> 204 | AO12: thiếu 4h
B13: 030903 | C13: Đào Chí Dũng | D13: E | G13: M | H13: M | I13: E | L13: M | M13: E | O13: M | Q13: M | R13: E | U13: E | V13: E | X13: M | Z13: HC | AA13: M | AB13: HC | AD13: E | AF13: M | AG13: HC | AI13: =COUNTIF(D13:AH13,"HC") -> 3 | AJ13: =COUNTIF(D13:AH13,"M") -> 8 | AK13: =COUNTIF(D13:AH13,"E") -> 7 | AM13: {=SUM(COUNTIF(D13:AH13,{"NL","P","B","T","SN"}))} -> 0 | AN13: =AI13*8+AJ13*12+AK13*12+AM13*8 -> 204 | AO13: thiếu 4h
B14: 031930 | C14: Phạm Ninh Toàn | E14: M | F14: E | I14: M | K14: E | N14: E | P14: HC | Q14: E | T14: M | U14: M | W14: HC | X14: E | Y14: E | Z14: E | AB14: M | AC14: M | AE14: M | AF14: E | AG14: E | AI14: =COUNTIF(D14:AH14,"HC") -> 2 | AJ14: =COUNTIF(D14:AH14,"M") -> 7 | AK14: =COUNTIF(D14:AH14,"E") -> 9 | AM14: {=SUM(COUNTIF(D14:AH14,{"NL","P","B","T","SN"}))} -> 0 | AN14: =AI14*8+AJ14*12+AK14*12+AM14*8 -> 208 | AO14: thiếu 4h
B15: 030322 | C15: Nguyễn Thái Uy | F15: M | G15: E | H15: E | J15: M | K15: M | L15: E | P15: E | R15: M | S15: E | U15: M | V15: M | Z15: M | AA15: E | AB15: E | AD15: M | AG15: M | AH15: M | AI15: =COUNTIF(D15:AH15,"HC") -> 0 | AJ15: =COUNTIF(D15:AH15,"M") -> 10 | AK15: =COUNTIF(D15:AH15,"E") -> 7 | AM15: {=SUM(COUNTIF(D15:AH15,{"NL","P","B","T","SN"}))} -> 0 | AN15: =AI15*8+AJ15*12+AK15*12+AM15*8 -> 204 | AO15: thiếu 4h
B16: 042014 | C16: Nguyễn Xuân Tuyền | E16: HC | F16: M | H16: HC | N16: M | P16: M | S16: HC | T16: M | W16: M | Z16: HC | AA16: M | AD16: M | AG16: HC | AH16: M | AI16: =COUNTIF(D16:AH16,"HC") -> 5 | AJ16: =COUNTIF(D16:AH16,"M") -> 8 | AK16: =COUNTIF(D16:AH16,"E") -> 0 | AM16: {=SUM(COUNTIF(D16:AH16,{"NL","P","B","T","SN"}))} -> 0 | AN16: =AI16*8+AJ16*12+AK16*12+AM16*8 -> 136
A17: DSP HDQ | B17: 030904 | C17: Trần Đình Đạt | E17: M | F17: M | G17: E | I17: M | L17: E | M17: E | O17: M | P17: E | R17: M | S17: E | T17: E | V17: M | W17: E | Y17: E | Z17: E | AB17: M | AG17: E | AI17: =COUNTIF(D17:AH17,"HC") -> 0 | AJ17: =COUNTIF(D17:AH17,"M") -> 7 | AK17: =COUNTIF(D17:AH17,"E") -> 10 | AM17: {=SUM(COUNTIF(D17:AH17,{"NL","P","B","T","SN"}))} -> 0 | AN17: =AI17*8+AJ17*12+AK17*12+AM17*8 -> 204 | AO17: thiếu 4h
B18: 030905 | C18: Nguyễn Trương Hoàng Hưng | D18: M | E18: E | I18: M | J18: E | K18: E | N18: M | O18: E | S18: M | T18: E | V18: M | W18: M | AA18: M | AB18: E | AC18: E | AE18: M | AF18: E | AH18: M | AI18: =COUNTIF(D18:AH18,"HC") -> 0 | AJ18: =COUNTIF(D18:AH18,"M") -> 9 | AK18: =COUNTIF(D18:AH18,"E") -> 8 | AM18: {=SUM(COUNTIF(D18:AH18,{"NL","P","B","T","SN"}))} -> 0 | AN18: =AI18*8+AJ18*12+AK18*12+AM18*8 -> 204 | AO18: thiếu 4h
B19: 030841 | C19: Vũ Hoàng Long | F19: E | H19: M | I19: E | K19: M | L19: M | M19: E | Q19: M | R19: E | U19: M | X19: E | Z19: M | AA19: E | AC19: M | AD19: M | AE19: E | AG19: M | AH19: E | AI19: =COUNTIF(D19:AH19,"HC") -> 0 | AJ19: =COUNTIF(D19:AH19,"M") -> 9 | AK19: =COUNTIF(D19:AH19,"E") -> 8 | AM19: {=SUM(COUNTIF(D19:AH19,{"NL","P","B","T","SN"}))} -> 0 | AN19: =AI19*8+AJ19*12+AK19*12+AM19*8 -> 204 | AO19: thiếu 4h
B20: 031845 | C20: Nguyễn Ngọc Long | F20: M | G20: M | H20: E | J20: M | L20: M | M20: M | N20: E | P20: M | Q20: E | T20: M | U20: E | V20: E | X20: M | Y20: M | AD20: E | AF20: M | AG20: E | AI20: =COUNTIF(D20:AH20,"HC") -> 0 | AJ20: =COUNTIF(D20:AH20,"M") -> 10 | AK20: =COUNTIF(D20:AH20,"E") -> 7 | AM20: {=SUM(COUNTIF(D20:AH20,{"NL","P","B","T","SN"}))} -> 0 | AN20: =AI20*8+AJ20*12+AK20*12+AM20*8 -> 204 | AO20: thiếu 4h
B21: 030906 | C21: Vũ Hoàng Hải | D21: E | E21: E | AI21: =COUNTIF(D21:AH21,"HC") -> 0 | AJ21: =COUNTIF(D21:AH21,"M") -> 0 | AK21: =COUNTIF(D21:AH21,"E") -> 2 | AM21: {=SUM(COUNTIF(D21:AH21,{"NL","P","B","T","SN"}))} -> 0 | AN21: =AI21*8+AJ21*12+AK21*12+AM21*8 -> 24
A22: DSP ASST HDQ | B22: 039278 | C22: Nguyền Kiều Huyền Chi | E22: HC | F22: HC | G22: HC | H22: HC | I22: HC | J22: M | K22: E | M22: M | N22: M | O22: E | R22: M | S22: E | U22: M | W22: E | Z22: M | AA22: E | AD22: M | AE22: E | AH22: M | AI22: =COUNTIF(D22:AH22,"HC") -> 5 | AJ22: =COUNTIF(D22:AH22,"M") -> 8 | AK22: =COUNTIF(D22:AH22,"E") -> 6 | AM22: {=SUM(COUNTIF(D22:AH22,{"NL","P","B","T","SN"}))} -> 0 | AN22: =AI22*8+AJ22*12+AK22*12+AM22*8 -> 208
B23: 039280 | C23: Đặng Thảo Linh | E23: HC | F23: HC | G23: HC | H23: HC | I23: HC | K23: M | L23: E | O23: M | P23: E | R23: M | S23: M | T23: E | V23: M | W23: M | X23: E | Z23: M | AB23: E | AE23: M | AF23: E | AI23: =COUNTIF(D23:AH23,"HC") -> 5 | AJ23: =COUNTIF(D23:AH23,"M") -> 8 | AK23: =COUNTIF(D23:AH23,"E") -> 6 | AM23: {=SUM(COUNTIF(D23:AH23,{"NL","P","B","T","SN"}))} -> 0 | AN23: =AI23*8+AJ23*12+AK23*12+AM23*8 -> 208
B24: 039276 | C24: Bùi Việt Anh | E24: HC | F24: HC | G24: HC | H24: HC | I24: HC | L24: M | M24: E | O24: M | P24: M | Q24: E | T24: M | U24: E | X24: M | Y24: E | AA24: M | AB24: M | AC24: E | AF24: M | AG24: E | AI24: =COUNTIF(D24:AH24,"HC") -> 5 | AJ24: =COUNTIF(D24:AH24,"M") -> 8 | AK24: =COUNTIF(D24:AH24,"E") -> 6 | AM24: {=SUM(COUNTIF(D24:AH24,{"NL","P","B","T","SN"}))} -> 0 | AN24: =AI24*8+AJ24*12+AK24*12+AM24*8 -> 208
B25: 039274 | C25: Đỗ Nam Anh | E25: HC | F25: HC | G25: HC | H25: HC | I25: HC | J25: E | N25: E | Q25: M | R25: E | U25: M | V25: E | X25: M | Y25: M | Z25: E | AB25: M | AC25: M | AD25: E | AG25: M | AH25: E | AI25: =COUNTIF(D25:AH25,"HC") -> 5 | AJ25: =COUNTIF(D25:AH25,"M") -> 7 | AK25: =COUNTIF(D25:AH25,"E") -> 7 | AM25: {=SUM(COUNTIF(D25:AH25,{"NL","P","B","T","SN"}))} -> 0 | AN25: =AI25*8+AJ25*12+AK25*12+AM25*8 -> 208
A26: DSP SGN | B26: 031844 | C26: Nguyễn Hoàng Huy | E26: M | F26: M | G26: E | I26: M | J26: E | L26: E | N26: M | O26: M | P26: E | R26: M | S26: E | T26: E | V26: E | W26: HC | X26: E | AD26: E | AE26: E | AG26: M | AI26: =COUNTIF(D26:AH26,"HC") -> 1 | AJ26: =COUNTIF(D26:AH26,"M") -> 7 | AK26: =COUNTIF(D26:AH26,"E") -> 10 | AM26: {=SUM(COUNTIF(D26:AH26,{"NL","P","B","T","SN"}))} -> 0 | AN26: =AI26*8+AJ26*12+AK26*12+AM26*8 -> 212
B27: 031843 | C27: Lương Trung Hiếu | D27: E | F27: E | H27: M | M27: E | N27: E | P27: E | Q27: E | S27: E | U27: HC | V27: M | W27: E | Y27: E | Z27: E | AB27: M | AC27: M | AD27: M | AF27: E | AG27: E | AI27: =COUNTIF(D27:AH27,"HC") -> 1 | AJ27: =COUNTIF(D27:AH27,"M") -> 5 | AK27: =COUNTIF(D27:AH27,"E") -> 12 | AM27: {=SUM(COUNTIF(D27:AH27,{"NL","P","B","T","SN"}))} -> 0 | AN27: =AI27*8+AJ27*12+AK27*12+AM27*8 -> 212
B28: 031846 | C28: Nguyễn Phúc Thịnh | G28: M | H28: E | I28: E | K28: M | L28: M | M28: M | N28: HC | O28: E | Q28: M | R28: E | T28: M | U28: E | W28: M | X28: M | Y28: M | AA28: M | AB28: E | AH28: E | AI28: =COUNTIF(D28:AH28,"HC") -> 1 | AJ28: =COUNTIF(D28:AH28,"M") -> 10 | AK28: =COUNTIF(D28:AH28,"E") -> 7 | AM28: {=SUM(COUNTIF(D28:AH28,{"NL","P","B","T","SN"}))} -> 0 | AN28: =AI28*8+AJ28*12+AK28*12+AM28*8 -> 212
B29: 031847 | C29: Hoàng Bảo Ngọc | D29: M | E29: E | G29: HC | I29: M | J29: M | K29: E | M29: M | P29: M | R29: M | S29: M | U29: M | X29: E | Z29: M | AA29: E | AC29: E | AE29: M | AF29: M | AH29: M | AI29: =COUNTIF(D29:AH29,"HC") -> 1 | AJ29: =COUNTIF(D29:AH29,"M") -> 12 | AK29: =COUNTIF(D29:AH29,"E") -> 5 | AM29: {=SUM(COUNTIF(D29:AH29,{"NL","P","B","T","SN"}))} -> 0 | AN29: =AI29*8+AJ29*12+AK29*12+AM29*8 -> 212
A30: DSP PQC | B30: 041863 | C30: Lê Ngọc Thành Tài | E30: HC | F30: HC | G30: HC | I30: HC | J30: M | L30: C9 | M30: C9 | O30: E | Q30: M | S30: C9 | U30: M | V30: E | X30: M | AA30: E | AC30: M | AD30: E | AF30: C9 | AG30: C9 | AH30: E | AI30: =COUNTIF(D30:AH30,"HC") -> 4 | AJ30: =COUNTIF(D30:AH30,"M") -> 5 | AK30: =COUNTIF(D30:AH30,"E") -> 5 | AL30: =COUNTIF(D30:AH30,"C9") -> 5 | AM30: {=SUM(COUNTIF(D30:AH30,{"NL","P","B","T","SN"}))} -> 0 | AN30: =AI30*8+AJ30*12+AK30*12+AL30*12+AM30*8 -> 212
B31: 041865 | C31: Nguyễn Đức Lộc | E31: HC | F31: HC | G31: HC | I31: HC | J31: E | M31: M | N31: C9 | P31: C9 | Q31: E | R31: C9 | T31: M | U31: E | W31: M | X31: E | Z31: C9 | AB31: M | AC31: E | AE31: M | AG31: C9 | AI31: =COUNTIF(D31:AH31,"HC") -> 4 | AJ31: =COUNTIF(D31:AH31,"M") -> 5 | AK31: =COUNTIF(D31:AH31,"E") -> 5 | AL31: =COUNTIF(D31:AH31,"C9") -> 5 | AM31: {=SUM(COUNTIF(D31:AH31,{"NL","P","B","T","SN"}))} -> 0 | AN31: =AI31*8+AJ31*12+AK31*12+AL31*12+AM31*8 -> 212
B32: 041867 | C32: Phan Thành Nghĩa | E32: HC | F32: HC | G32: HC | I32: HC | J32: C9 | K32: C9 | M32: E | O32: M | P32: C9 | Q32: C9 | T32: E | V32: M | W32: E | Y32: C9 | AA32: M | AB32: E | AD32: M | AE32: E | AH32: M | AI32: =COUNTIF(D32:AH32,"HC") -> 4 | AJ32: =COUNTIF(D32:AH32,"M") -> 5 | AK32: =COUNTIF(D32:AH32,"E") -> 5 | AL32: =COUNTIF(D32:AH32,"C9") -> 5 | AM32: {=SUM(COUNTIF(D32:AH32,{"NL","P","B","T","SN"}))} -> 0 | AN32: =AI32*8+AJ32*12+AK32*12+AL32*12+AM32*8 -> 212
A35: Check cơ cấu | B35: DM | C35: HC | D35: =COUNTIF(D12:D16,"HC") -> 0 | E35: =COUNTIF(E12:E16,"HC") -> 1 | F35: =COUNTIF(F12:F16,"HC") -> 0 | G35: =COUNTIF(G12:G16,"HC") -> 0 | H35: =COUNTIF(H12:H16,"HC") -> 1 | I35: =COUNTIF(I12:I16,"HC") -> 0 | J35: =COUNTIF(J12:J16,"HC") -> 0 | K35: =COUNTIF(K12:K16,"HC") -> 0 | ... AH35: =COUNTIF(AH12:AH16,"HC") -> 0
C36: M | D36: =COUNTIF(D12:D16,"M") -> 1 | E36: =COUNTIF(E12:E16,"M") -> 1 | F36: =COUNTIF(F12:F16,"M") -> 2 | G36: =COUNTIF(G12:G16,"M") -> 1 | H36: =COUNTIF(H12:H16,"M") -> 2 | I36: =COUNTIF(I12:I16,"M") -> 2 | J36: =COUNTIF(J12:J16,"M") -> 1 | K36: =COUNTIF(K12:K16,"M") -> 1 | ... AH36: =COUNTIF(AH12:AH16,"M") -> 2
C37: E | D37: =COUNTIF(D12:D16,"E") -> 1 | E37: =COUNTIF(E12:E16,"E") -> 1 | F37: =COUNTIF(F12:F16,"E") -> 1 | G37: =COUNTIF(G12:G16,"E") -> 1 | H37: =COUNTIF(H12:H16,"E") -> 1 | I37: =COUNTIF(I12:I16,"E") -> 1 | J37: =COUNTIF(J12:J16,"E") -> 1 | K37: =COUNTIF(K12:K16,"E") -> 1 | ... AH37: =COUNTIF(AH12:AH16,"E") -> 1
B38: DSP HDQ | C38: HC | D38: =COUNTIF(D17:D21,"HC") -> 0 | E38: =COUNTIF(E17:E21,"HC") -> 0 | F38: =COUNTIF(F17:F21,"HC") -> 0 | G38: =COUNTIF(G17:G21,"HC") -> 0 | H38: =COUNTIF(H17:H21,"HC") -> 0 | I38: =COUNTIF(I17:I21,"HC") -> 0 | J38: =COUNTIF(J17:J21,"HC") -> 0 | K38: =COUNTIF(K17:K21,"HC") -> 0 | ... AH38: =COUNTIF(AH17:AH21,"HC") -> 0
C39: M | D39: =COUNTIF(D17:D21,"M") -> 1 | E39: =COUNTIF(E17:E21,"M") -> 1 | F39: =COUNTIF(F17:F21,"M") -> 2 | G39: =COUNTIF(G17:G21,"M") -> 1 | H39: =COUNTIF(H17:H21,"M") -> 1 | I39: =COUNTIF(I17:I21,"M") -> 2 | J39: =COUNTIF(J17:J21,"M") -> 1 | K39: =COUNTIF(K17:K21,"M") -> 1 | ... AH39: =COUNTIF(AH17:AH21,"M") -> 1
C40: E | D40: =COUNTIF(D17:D21,"E") -> 1 | E40: =COUNTIF(E17:E21,"E") -> 2 | F40: =COUNTIF(F17:F21,"E") -> 1 | G40: =COUNTIF(G17:G21,"E") -> 1 | H40: =COUNTIF(H17:H21,"E") -> 1 | I40: =COUNTIF(I17:I21,"E") -> 1 | J40: =COUNTIF(J17:J21,"E") -> 1 | K40: =COUNTIF(K17:K21,"E") -> 1 | ... AH40: =COUNTIF(AH17:AH21,"E") -> 1
B41: DSP ASS | C41: HC | D41: =COUNTIF(D22:D25,"HC") -> 0 | E41: =COUNTIF(E22:E25,"HC") -> 4 | F41: =COUNTIF(F22:F25,"HC") -> 4 | G41: =COUNTIF(G22:G25,"HC") -> 4 | H41: =COUNTIF(H22:H25,"HC") -> 4 | I41: =COUNTIF(I22:I25,"HC") -> 4 | J41: =COUNTIF(J22:J25,"HC") -> 0 | K41: =COUNTIF(K22:K25,"HC") -> 0 | ... AH41: =COUNTIF(AH22:AH25,"HC") -> 0
C42: M | D42: =COUNTIF(D22:D25,"M") -> 0 | E42: =COUNTIF(E22:E25,"M") -> 0 | F42: =COUNTIF(F22:F25,"M") -> 0 | G42: =COUNTIF(G22:G25,"M") -> 0 | H42: =COUNTIF(H22:H25,"M") -> 0 | I42: =COUNTIF(I22:I25,"M") -> 0 | J42: =COUNTIF(J22:J25,"M") -> 1 | K42: =COUNTIF(K22:K25,"M") -> 1 | ... AH42: =COUNTIF(AH22:AH25,"M") -> 1
C43: E | D43: =COUNTIF(D22:D25,"E") -> 0 | E43: =COUNTIF(E22:E25,"E") -> 0 | F43: =COUNTIF(F22:F25,"E") -> 0 | G43: =COUNTIF(G22:G25,"E") -> 0 | H43: =COUNTIF(H22:H25,"E") -> 0 | I43: =COUNTIF(I22:I25,"E") -> 0 | J43: =COUNTIF(J22:J25,"E") -> 1 | K43: =COUNTIF(K22:K25,"E") -> 1 | ... AH43: =COUNTIF(AH22:AH25,"E") -> 1
B44: DSP SGN | C44: HC | D44: =COUNTIF(D26:D29,"HC") -> 0 | E44: =COUNTIF(E26:E29,"HC") -> 0 | F44: =COUNTIF(F26:F29,"HC") -> 0 | G44: =COUNTIF(G26:G29,"HC") -> 1 | H44: =COUNTIF(H26:H29,"HC") -> 0 | I44: =COUNTIF(I26:I29,"HC") -> 0 | J44: =COUNTIF(J26:J29,"HC") -> 0 | K44: =COUNTIF(K26:K29,"HC") -> 0 | ... AH44: =COUNTIF(AH26:AH29,"HC") -> 0
C45: M | D45: =COUNTIF(D26:D29,"M") -> 1 | E45: =COUNTIF(E26:E29,"M") -> 1 | F45: =COUNTIF(F26:F29,"M") -> 1 | G45: =COUNTIF(G26:G29,"M") -> 1 | H45: =COUNTIF(H26:H29,"M") -> 1 | I45: =COUNTIF(I26:I29,"M") -> 2 | J45: =COUNTIF(J26:J29,"M") -> 1 | K45: =COUNTIF(K26:K29,"M") -> 1 | ... AH45: =COUNTIF(AH26:AH29,"M") -> 1
...

Sheet Import Shift
A1: MÃ NV | B1: Họ và Tên NV | C1: 26/07/2026 | D1: =TEXT(DATE(RIGHT(C1,4), MID(C1,4,2), LEFT(C1,2)+1),"DD/MM/YYYY") -> 27/07/2026 | E1: =TEXT(DATE(RIGHT(D1,4), MID(D1,4,2), LEFT(D1,2)+1),"DD/MM/YYYY") -> 28/07/2026 | F1: =TEXT(DATE(RIGHT(E1,4), MID(E1,4,2), LEFT(E1,2)+1),"DD/MM/YYYY") -> 29/07/2026 | G1: =TEXT(DATE(RIGHT(F1,4), MID(F1,4,2), LEFT(F1,2)+1),"DD/MM/YYYY") -> 30/07/2026 | H1: =TEXT(DATE(RIGHT(G1,4), MID(G1,4,2), LEFT(G1,2)+1),"DD/MM/YYYY") -> 31/07/2026 | I1: =TEXT(DATE(RIGHT(H1,4), MID(H1,4,2), LEFT(H1,2)+1),"DD/MM/YYYY") -> 01/08/2026 | J1: =TEXT(DATE(RIGHT(I1,4), MID(I1,4,2), LEFT(I1,2)+1),"DD/MM/YYYY") -> 02/08/2026 | K1: =TEXT(DATE(RIGHT(J1,4), MID(J1,4,2), LEFT(J1,2)+1),"DD/MM/YYYY") -> 03/08/2026 | ... AG1: =TEXT(DATE(RIGHT(AF1,4), MID(AF1,4,2), LEFT(AF1,2)+1),"DD/MM/YYYY") -> 25/08/2026
A2: 030346 | B2: Đàm Xuân Hiến | C2: {=_xlfn.IFS(OCD!D12="","OFF",OCD!D12="HC","C087",OCD!D12="M","C510",OCD!D12="E","C519",OCD!D12="C9","C678", TRUE,"")} -> C510 | D2: {=_xlfn.IFS(OCD!E12="","OFF",OCD!E12="HC","C087",OCD!E12="M","C510",OCD!E12="E","C519",OCD!E12="C9","C678", TRUE,"")} -> C519 | E2: {=_xlfn.IFS(OCD!F12="","OFF",OCD!F12="HC","C087",OCD!F12="M","C510",OCD!F12="E","C519",OCD!F12="C9","C678", TRUE,"")} -> OFF | F2: {=_xlfn.IFS(OCD!G12="","OFF",OCD!G12="HC","C087",OCD!G12="M","C510",OCD!G12="E","C519",OCD!G12="C9","C678", TRUE,"")} -> OFF | G2: {=_xlfn.IFS(OCD!H12="","OFF",OCD!H12="HC","C087",OCD!H12="M","C510",OCD!H12="E","C519",OCD!H12="C9","C678", TRUE,"")} -> C510 | H2: {=_xlfn.IFS(OCD!I12="","OFF",OCD!I12="HC","C087",OCD!I12="M","C510",OCD!I12="E","C519",OCD!I12="C9","C678", TRUE,"")} -> C510 | I2: {=_xlfn.IFS(OCD!J12="","OFF",OCD!J12="HC","C087",OCD!J12="M","C510",OCD!J12="E","C519",OCD!J12="C9","C678", TRUE,"")} -> C519 | J2: {=_xlfn.IFS(OCD!K12="","OFF",OCD!K12="HC","C087",OCD!K12="M","C510",OCD!K12="E","C519",OCD!K12="C9","C678", TRUE,"")} -> OFF | ... AG2: {=_xlfn.IFS(OCD!AH12="","OFF",OCD!AH12="HC","C087",OCD!AH12="M","C510",OCD!AH12="E","C519",OCD!AH12="C9","C678", TRUE,"")} -> C519
A3: 030903 | B3: Đào Chí Dũng | C3: {=_xlfn.IFS(OCD!D13="","OFF",OCD!D13="HC","C087",OCD!D13="M","C510",OCD!D13="E","C519",OCD!D13="C9","C678", TRUE,"")} -> C519 | D3: {=_xlfn.IFS(OCD!E13="","OFF",OCD!E13="HC","C087",OCD!E13="M","C510",OCD!E13="E","C519",OCD!E13="C9","C678", TRUE,"")} -> OFF | E3: {=_xlfn.IFS(OCD!F13="","OFF",OCD!F13="HC","C087",OCD!F13="M","C510",OCD!F13="E","C519",OCD!F13="C9","C678", TRUE,"")} -> OFF | F3: {=_xlfn.IFS(OCD!G13="","OFF",OCD!G13="HC","C087",OCD!G13="M","C510",OCD!G13="E","C519",OCD!G13="C9","C678", TRUE,"")} -> C510 | G3: {=_xlfn.IFS(OCD!H13="","OFF",OCD!H13="HC","C087",OCD!H13="M","C510",OCD!H13="E","C519",OCD!H13="C9","C678", TRUE,"")} -> C510 | H3: {=_xlfn.IFS(OCD!I13="","OFF",OCD!I13="HC","C087",OCD!I13="M","C510",OCD!I13="E","C519",OCD!I13="C9","C678", TRUE,"")} -> C519 | I3: {=_xlfn.IFS(OCD!J13="","OFF",OCD!J13="HC","C087",OCD!J13="M","C510",OCD!J13="E","C519",OCD!J13="C9","C678", TRUE,"")} -> OFF | J3: {=_xlfn.IFS(OCD!K13="","OFF",OCD!K13="HC","C087",OCD!K13="M","C510",OCD!K13="E","C519",OCD!K13="C9","C678", TRUE,"")} -> OFF | ... AG3: {=_xlfn.IFS(OCD!AH13="","OFF",OCD!AH13="HC","C087",OCD!AH13="M","C510",OCD!AH13="E","C519",OCD!AH13="C9","C678", TRUE,"")} -> OFF
A4: 031930 | B4: Phạm Ninh Toàn | C4: {=_xlfn.IFS(OCD!D14="","OFF",OCD!D14="HC","C087",OCD!D14="M","C510",OCD!D14="E","C519",OCD!D14="C9","C678", TRUE,"")} -> OFF | D4: {=_xlfn.IFS(OCD!E14="","OFF",OCD!E14="HC","C087",OCD!E14="M","C510",OCD!E14="E","C519",OCD!E14="C9","C678", TRUE,"")} -> C510 | E4: {=_xlfn.IFS(OCD!F14="","OFF",OCD!F14="HC","C087",OCD!F14="M","C510",OCD!F14="E","C519",OCD!F14="C9","C678", TRUE,"")} -> C519 | F4: {=_xlfn.IFS(OCD!G14="","OFF",OCD!G14="HC","C087",OCD!G14="M","C510",OCD!G14="E","C519",OCD!G14="C9","C678", TRUE,"")} -> OFF | G4: {=_xlfn.IFS(OCD!H14="","OFF",OCD!H14="HC","C087",OCD!H14="M","C510",OCD!H14="E","C519",OCD!H14="C9","C678", TRUE,"")} -> OFF | H4: {=_xlfn.IFS(OCD!I14="","OFF",OCD!I14="HC","C087",OCD!I14="M","C510",OCD!I14="E","C519",OCD!I14="C9","C678", TRUE,"")} -> C510 | I4: {=_xlfn.IFS(OCD!J14="","OFF",OCD!J14="HC","C087",OCD!J14="M","C510",OCD!J14="E","C519",OCD!J14="C9","C678", TRUE,"")} -> OFF | J4: {=_xlfn.IFS(OCD!K14="","OFF",OCD!K14="HC","C087",OCD!K14="M","C510",OCD!K14="E","C519",OCD!K14="C9","C678", TRUE,"")} -> C519 | ... AG4: {=_xlfn.IFS(OCD!AH14="","OFF",OCD!AH14="HC","C087",OCD!AH14="M","C510",OCD!AH14="E","C519",OCD!AH14="C9","C678", TRUE,"")} -> OFF
A5: 030322 | B5: Nguyễn Thái Uy | C5: {=_xlfn.IFS(OCD!D15="","OFF",OCD!D15="HC","C087",OCD!D15="M","C510",OCD!D15="E","C519",OCD!D15="C9","C678", TRUE,"")} -> OFF | D5: {=_xlfn.IFS(OCD!E15="","OFF",OCD!E15="HC","C087",OCD!E15="M","C510",OCD!E15="E","C519",OCD!E15="C9","C678", TRUE,"")} -> OFF | E5: {=_xlfn.IFS(OCD!F15="","OFF",OCD!F15="HC","C087",OCD!F15="M","C510",OCD!F15="E","C519",OCD!F15="C9","C678", TRUE,"")} -> C510 | F5: {=_xlfn.IFS(OCD!G15="","OFF",OCD!G15="HC","C087",OCD!G15="M","C510",OCD!G15="E","C519",OCD!G15="C9","C678", TRUE,"")} -> C519 | G5: {=_xlfn.IFS(OCD!H15="","OFF",OCD!H15="HC","C087",OCD!H15="M","C510",OCD!H15="E","C519",OCD!H15="C9","C678", TRUE,"")} -> C519 | H5: {=_xlfn.IFS(OCD!I15="","OFF",OCD!I15="HC","C087",OCD!I15="M","C510",OCD!I15="E","C519",OCD!I15="C9","C678", TRUE,"")} -> OFF | I5: {=_xlfn.IFS(OCD!J15="","OFF",OCD!J15="HC","C087",OCD!J15="M","C510",OCD!J15="E","C519",OCD!J15="C9","C678", TRUE,"")} -> C510 | J5: {=_xlfn.IFS(OCD!K15="","OFF",OCD!K15="HC","C087",OCD!K15="M","C510",OCD!K15="E","C519",OCD!K15="C9","C678", TRUE,"")} -> C510 | ... AG5: {=_xlfn.IFS(OCD!AH15="","OFF",OCD!AH15="HC","C087",OCD!AH15="M","C510",OCD!AH15="E","C519",OCD!AH15="C9","C678", TRUE,"")} -> C510
A6: 031845 | B6: Nguyễn Ngọc Long | C6: {=_xlfn.IFS(OCD!D20="","OFF",OCD!D20="HC","C087",OCD!D20="M","C510",OCD!D20="E","C519",OCD!D20="C9","C678", TRUE,"")} -> OFF | D6: {=_xlfn.IFS(OCD!E20="","OFF",OCD!E20="HC","C087",OCD!E20="M","C510",OCD!E20="E","C519",OCD!E20="C9","C678", TRUE,"")} -> OFF | E6: {=_xlfn.IFS(OCD!F20="","OFF",OCD!F20="HC","C087",OCD!F20="M","C510",OCD!F20="E","C519",OCD!F20="C9","C678", TRUE,"")} -> C510 | F6: {=_xlfn.IFS(OCD!G20="","OFF",OCD!G20="HC","C087",OCD!G20="M","C510",OCD!G20="E","C519",OCD!G20="C9","C678", TRUE,"")} -> C510 | G6: {=_xlfn.IFS(OCD!H20="","OFF",OCD!H20="HC","C087",OCD!H20="M","C510",OCD!H20="E","C519",OCD!H20="C9","C678", TRUE,"")} -> C519 | H6: {=_xlfn.IFS(OCD!I20="","OFF",OCD!I20="HC","C087",OCD!I20="M","C510",OCD!I20="E","C519",OCD!I20="C9","C678", TRUE,"")} -> OFF | I6: {=_xlfn.IFS(OCD!J20="","OFF",OCD!J20="HC","C087",OCD!J20="M","C510",OCD!J20="E","C519",OCD!J20="C9","C678", TRUE,"")} -> C510 | J6: {=_xlfn.IFS(OCD!K20="","OFF",OCD!K20="HC","C087",OCD!K20="M","C510",OCD!K20="E","C519",OCD!K20="C9","C678", TRUE,"")} -> OFF | ... AG6: {=_xlfn.IFS(OCD!AH20="","OFF",OCD!AH20="HC","C087",OCD!AH20="M","C510",OCD!AH20="E","C519",OCD!AH20="C9","C678", TRUE,"")} -> OFF
A7: 042014 | B7: Nguyễn Xuân Tuyền | C7: {=_xlfn.IFS(OCD!D16="","OFF",OCD!D16="HC","C087",OCD!D16="M","C510",OCD!D16="E","C519",OCD!D16="C9","C678", TRUE,"")} -> OFF | D7: {=_xlfn.IFS(OCD!E16="","OFF",OCD!E16="HC","C087",OCD!E16="M","C510",OCD!E16="E","C519",OCD!E16="C9","C678", TRUE,"")} -> C087 | E7: {=_xlfn.IFS(OCD!F16="","OFF",OCD!F16="HC","C087",OCD!F16="M","C510",OCD!F16="E","C519",OCD!F16="C9","C678", TRUE,"")} -> C510 | F7: {=_xlfn.IFS(OCD!G16="","OFF",OCD!G16="HC","C087",OCD!G16="M","C510",OCD!G16="E","C519",OCD!G16="C9","C678", TRUE,"")} -> OFF | G7: {=_xlfn.IFS(OCD!H16="","OFF",OCD!H16="HC","C087",OCD!H16="M","C510",OCD!H16="E","C519",OCD!H16="C9","C678", TRUE,"")} -> C087 | H7: {=_xlfn.IFS(OCD!I16="","OFF",OCD!I16="HC","C087",OCD!I16="M","C510",OCD!I16="E","C519",OCD!I16="C9","C678", TRUE,"")} -> OFF | I7: {=_xlfn.IFS(OCD!J16="","OFF",OCD!J16="HC","C087",OCD!J16="M","C510",OCD!J16="E","C519",OCD!J16="C9","C678", TRUE,"")} -> OFF | J7: {=_xlfn.IFS(OCD!K16="","OFF",OCD!K16="HC","C087",OCD!K16="M","C510",OCD!K16="E","C519",OCD!K16="C9","C678", TRUE,"")} -> OFF | ... AG7: {=_xlfn.IFS(OCD!AH16="","OFF",OCD!AH16="HC","C087",OCD!AH16="M","C510",OCD!AH16="E","C519",OCD!AH16="C9","C678", TRUE,"")} -> C510
A8: 030904 | B8: Trần Đình Đạt | C8: {=_xlfn.IFS(OCD!D17="","OFF",OCD!D17="HC","C087",OCD!D17="M","C510",OCD!D17="E","C519",OCD!D17="C9","C678", TRUE,"")} -> OFF | D8: {=_xlfn.IFS(OCD!E17="","OFF",OCD!E17="HC","C087",OCD!E17="M","C510",OCD!E17="E","C519",OCD!E17="C9","C678", TRUE,"")} -> C510 | E8: {=_xlfn.IFS(OCD!F17="","OFF",OCD!F17="HC","C087",OCD!F17="M","C510",OCD!F17="E","C519",OCD!F17="C9","C678", TRUE,"")} -> C510 | F8: {=_xlfn.IFS(OCD!G17="","OFF",OCD!G17="HC","C087",OCD!G17="M","C510",OCD!G17="E","C519",OCD!G17="C9","C678", TRUE,"")} -> C519 | G8: {=_xlfn.IFS(OCD!H17="","OFF",OCD!H17="HC","C087",OCD!H17="M","C510",OCD!H17="E","C519",OCD!H17="C9","C678", TRUE,"")} -> OFF | H8: {=_xlfn.IFS(OCD!I17="","OFF",OCD!I17="HC","C087",OCD!I17="M","C510",OCD!I17="E","C519",OCD!I17="C9","C678", TRUE,"")} -> C510 | I8: {=_xlfn.IFS(OCD!J17="","OFF",OCD!J17="HC","C087",OCD!J17="M","C510",OCD!J17="E","C519",OCD!J17="C9","C678", TRUE,"")} -> OFF | J8: {=_xlfn.IFS(OCD!K17="","OFF",OCD!K17="HC","C087",OCD!K17="M","C510",OCD!K17="E","C519",OCD!K17="C9","C678", TRUE,"")} -> OFF | ... AG8: {=_xlfn.IFS(OCD!AH17="","OFF",OCD!AH17="HC","C087",OCD!AH17="M","C510",OCD!AH17="E","C519",OCD!AH17="C9","C678", TRUE,"")} -> OFF
A9: 030905 | B9: Nguyễn Trương Hoàng Hưng | C9: {=_xlfn.IFS(OCD!D18="","OFF",OCD!D18="HC","C087",OCD!D18="M","C510",OCD!D18="E","C519",OCD!D18="C9","C678", TRUE,"")} -> C510 | D9: {=_xlfn.IFS(OCD!E18="","OFF",OCD!E18="HC","C087",OCD!E18="M","C510",OCD!E18="E","C519",OCD!E18="C9","C678", TRUE,"")} -> C519 | E9: {=_xlfn.IFS(OCD!F18="","OFF",OCD!F18="HC","C087",OCD!F18="M","C510",OCD!F18="E","C519",OCD!F18="C9","C678", TRUE,"")} -> OFF | F9: {=_xlfn.IFS(OCD!G18="","OFF",OCD!G18="HC","C087",OCD!G18="M","C510",OCD!G18="E","C519",OCD!G18="C9","C678", TRUE,"")} -> OFF | G9: {=_xlfn.IFS(OCD!H18="","OFF",OCD!H18="HC","C087",OCD!H18="M","C510",OCD!H18="E","C519",OCD!H18="C9","C678", TRUE,"")} -> OFF | H9: {=_xlfn.IFS(OCD!I18="","OFF",OCD!I18="HC","C087",OCD!I18="M","C510",OCD!I18="E","C519",OCD!I18="C9","C678", TRUE,"")} -> C510 | I9: {=_xlfn.IFS(OCD!J18="","OFF",OCD!J18="HC","C087",OCD!J18="M","C510",OCD!J18="E","C519",OCD!J18="C9","C678", TRUE,"")} -> C519 | J9: {=_xlfn.IFS(OCD!K18="","OFF",OCD!K18="HC","C087",OCD!K18="M","C510",OCD!K18="E","C519",OCD!K18="C9","C678", TRUE,"")} -> C519 | ... AG9: {=_xlfn.IFS(OCD!AH18="","OFF",OCD!AH18="HC","C087",OCD!AH18="M","C510",OCD!AH18="E","C519",OCD!AH18="C9","C678", TRUE,"")} -> C510
A10: 030906 | B10: Vũ Hoàng Hải | C10: {=_xlfn.IFS(OCD!D21="","OFF",OCD!D21="HC","C087",OCD!D21="M","C510",OCD!D21="E","C519",OCD!D21="C9","C678", TRUE,"")} -> C519 | D10: {=_xlfn.IFS(OCD!E21="","OFF",OCD!E21="HC","C087",OCD!E21="M","C510",OCD!E21="E","C519",OCD!E21="C9","C678", TRUE,"")} -> C519 | E10: {=_xlfn.IFS(OCD!F21="","OFF",OCD!F21="HC","C087",OCD!F21="M","C510",OCD!F21="E","C519",OCD!F21="C9","C678", TRUE,"")} -> OFF | F10: {=_xlfn.IFS(OCD!G21="","OFF",OCD!G21="HC","C087",OCD!G21="M","C510",OCD!G21="E","C519",OCD!G21="C9","C678", TRUE,"")} -> OFF | G10: {=_xlfn.IFS(OCD!H21="","OFF",OCD!H21="HC","C087",OCD!H21="M","C510",OCD!H21="E","C519",OCD!H21="C9","C678", TRUE,"")} -> OFF | H10: {=_xlfn.IFS(OCD!I21="","OFF",OCD!I21="HC","C087",OCD!I21="M","C510",OCD!I21="E","C519",OCD!I21="C9","C678", TRUE,"")} -> OFF | I10: {=_xlfn.IFS(OCD!J21="","OFF",OCD!J21="HC","C087",OCD!J21="M","C510",OCD!J21="E","C519",OCD!J21="C9","C678", TRUE,"")} -> OFF | J10: {=_xlfn.IFS(OCD!K21="","OFF",OCD!K21="HC","C087",OCD!K21="M","C510",OCD!K21="E","C519",OCD!K21="C9","C678", TRUE,"")} -> OFF | ... AG10: {=_xlfn.IFS(OCD!AH21="","OFF",OCD!AH21="HC","C087",OCD!AH21="M","C510",OCD!AH21="E","C519",OCD!AH21="C9","C678", TRUE,"")} -> OFF
A11: 030841 | B11: Vũ Hoàng Long | C11: {=_xlfn.IFS(OCD!D19="","OFF",OCD!D19="HC","C087",OCD!D19="M","C510",OCD!D19="E","C519",OCD!D19="C9","C678", TRUE,"")} -> OFF | D11: {=_xlfn.IFS(OCD!E19="","OFF",OCD!E19="HC","C087",OCD!E19="M","C510",OCD!E19="E","C519",OCD!E19="C9","C678", TRUE,"")} -> OFF | E11: {=_xlfn.IFS(OCD!F19="","OFF",OCD!F19="HC","C087",OCD!F19="M","C510",OCD!F19="E","C519",OCD!F19="C9","C678", TRUE,"")} -> C519 | F11: {=_xlfn.IFS(OCD!G19="","OFF",OCD!G19="HC","C087",OCD!G19="M","C510",OCD!G19="E","C519",OCD!G19="C9","C678", TRUE,"")} -> OFF | G11: {=_xlfn.IFS(OCD!H19="","OFF",OCD!H19="HC","C087",OCD!H19="M","C510",OCD!H19="E","C519",OCD!H19="C9","C678", TRUE,"")} -> C510 | H11: {=_xlfn.IFS(OCD!I19="","OFF",OCD!I19="HC","C087",OCD!I19="M","C510",OCD!I19="E","C519",OCD!I19="C9","C678", TRUE,"")} -> C519 | I11: {=_xlfn.IFS(OCD!J19="","OFF",OCD!J19="HC","C087",OCD!J19="M","C510",OCD!J19="E","C519",OCD!J19="C9","C678", TRUE,"")} -> OFF | J11: {=_xlfn.IFS(OCD!K19="","OFF",OCD!K19="HC","C087",OCD!K19="M","C510",OCD!K19="E","C519",OCD!K19="C9","C678", TRUE,"")} -> C510 | ... AG11: {=_xlfn.IFS(OCD!AH19="","OFF",OCD!AH19="HC","C087",OCD!AH19="M","C510",OCD!AH19="E","C519",OCD!AH19="C9","C678", TRUE,"")} -> C519
A12: 039278 | B12: Nguyền Kiều Huyền Chi | C12: {=_xlfn.IFS(OCD!D22="","OFF",OCD!D22="HC","C087",OCD!D22="M","C510",OCD!D22="E","C519",OCD!D22="C9","C678", TRUE,"")} -> OFF | D12: {=_xlfn.IFS(OCD!E22="","OFF",OCD!E22="HC","C087",OCD!E22="M","C510",OCD!E22="E","C519",OCD!E22="C9","C678", TRUE,"")} -> C087 | E12: {=_xlfn.IFS(OCD!F22="","OFF",OCD!F22="HC","C087",OCD!F22="M","C510",OCD!F22="E","C519",OCD!F22="C9","C678", TRUE,"")} -> C087 | F12: {=_xlfn.IFS(OCD!G22="","OFF",OCD!G22="HC","C087",OCD!G22="M","C510",OCD!G22="E","C519",OCD!G22="C9","C678", TRUE,"")} -> C087 | G12: {=_xlfn.IFS(OCD!H22="","OFF",OCD!H22="HC","C087",OCD!H22="M","C510",OCD!H22="E","C519",OCD!H22="C9","C678", TRUE,"")} -> C087 | H12: {=_xlfn.IFS(OCD!I22="","OFF",OCD!I22="HC","C087",OCD!I22="M","C510",OCD!I22="E","C519",OCD!I22="C9","C678", TRUE,"")} -> C087 | I12: {=_xlfn.IFS(OCD!J22="","OFF",OCD!J22="HC","C087",OCD!J22="M","C510",OCD!J22="E","C519",OCD!J22="C9","C678", TRUE,"")} -> C510 | J12: {=_xlfn.IFS(OCD!K22="","OFF",OCD!K22="HC","C087",OCD!K22="M","C510",OCD!K22="E","C519",OCD!K22="C9","C678", TRUE,"")} -> C519 | ... AG12: {=_xlfn.IFS(OCD!AH22="","OFF",OCD!AH22="HC","C087",OCD!AH22="M","C510",OCD!AH22="E","C519",OCD!AH22="C9","C678", TRUE,"")} -> C510
A13: 039280 | B13: Đặng Thảo Linh | C13: {=_xlfn.IFS(OCD!D23="","OFF",OCD!D23="HC","C087",OCD!D23="M","C510",OCD!D23="E","C519",OCD!D23="C9","C678", TRUE,"")} -> OFF | D13: {=_xlfn.IFS(OCD!E23="","OFF",OCD!E23="HC","C087",OCD!E23="M","C510",OCD!E23="E","C519",OCD!E23="C9","C678", TRUE,"")} -> C087 | E13: {=_xlfn.IFS(OCD!F23="","OFF",OCD!F23="HC","C087",OCD!F23="M","C510",OCD!F23="E","C519",OCD!F23="C9","C678", TRUE,"")} -> C087 | F13: {=_xlfn.IFS(OCD!G23="","OFF",OCD!G23="HC","C087",OCD!G23="M","C510",OCD!G23="E","C519",OCD!G23="C9","C678", TRUE,"")} -> C087 | G13: {=_xlfn.IFS(OCD!H23="","OFF",OCD!H23="HC","C087",OCD!H23="M","C510",OCD!H23="E","C519",OCD!H23="C9","C678", TRUE,"")} -> C087 | H13: {=_xlfn.IFS(OCD!I23="","OFF",OCD!I23="HC","C087",OCD!I23="M","C510",OCD!I23="E","C519",OCD!I23="C9","C678", TRUE,"")} -> C087 | I13: {=_xlfn.IFS(OCD!J23="","OFF",OCD!J23="HC","C087",OCD!J23="M","C510",OCD!J23="E","C519",OCD!J23="C9","C678", TRUE,"")} -> OFF | J13: {=_xlfn.IFS(OCD!K23="","OFF",OCD!K23="HC","C087",OCD!K23="M","C510",OCD!K23="E","C519",OCD!K23="C9","C678", TRUE,"")} -> C510 | ... AG13: {=_xlfn.IFS(OCD!AH23="","OFF",OCD!AH23="HC","C087",OCD!AH23="M","C510",OCD!AH23="E","C519",OCD!AH23="C9","C678", TRUE,"")} -> OFF
A14: 039276 | B14: Bùi Việt Anh | C14: {=_xlfn.IFS(OCD!D24="","OFF",OCD!D24="HC","C087",OCD!D24="M","C510",OCD!D24="E","C519",OCD!D24="C9","C678", TRUE,"")} -> OFF | D14: {=_xlfn.IFS(OCD!E24="","OFF",OCD!E24="HC","C087",OCD!E24="M","C510",OCD!E24="E","C519",OCD!E24="C9","C678", TRUE,"")} -> C087 | E14: {=_xlfn.IFS(OCD!F24="","OFF",OCD!F24="HC","C087",OCD!F24="M","C510",OCD!F24="E","C519",OCD!F24="C9","C678", TRUE,"")} -> C087 | F14: {=_xlfn.IFS(OCD!G24="","OFF",OCD!G24="HC","C087",OCD!G24="M","C510",OCD!G24="E","C519",OCD!G24="C9","C678", TRUE,"")} -> C087 | G14: {=_xlfn.IFS(OCD!H24="","OFF",OCD!H24="HC","C087",OCD!H24="M","C510",OCD!H24="E","C519",OCD!H24="C9","C678", TRUE,"")} -> C087 | H14: {=_xlfn.IFS(OCD!I24="","OFF",OCD!I24="HC","C087",OCD!I24="M","C510",OCD!I24="E","C519",OCD!I24="C9","C678", TRUE,"")} -> C087 | I14: {=_xlfn.IFS(OCD!J24="","OFF",OCD!J24="HC","C087",OCD!J24="M","C510",OCD!J24="E","C519",OCD!J24="C9","C678", TRUE,"")} -> OFF | J14: {=_xlfn.IFS(OCD!K24="","OFF",OCD!K24="HC","C087",OCD!K24="M","C510",OCD!K24="E","C519",OCD!K24="C9","C678", TRUE,"")} -> OFF | ... AG14: {=_xlfn.IFS(OCD!AH24="","OFF",OCD!AH24="HC","C087",OCD!AH24="M","C510",OCD!AH24="E","C519",OCD!AH24="C9","C678", TRUE,"")} -> OFF
A15: 039274 | B15: Đỗ Nam Anh | C15: {=_xlfn.IFS(OCD!D25="","OFF",OCD!D25="HC","C087",OCD!D25="M","C510",OCD!D25="E","C519",OCD!D25="C9","C678", TRUE,"")} -> OFF | D15: {=_xlfn.IFS(OCD!E25="","OFF",OCD!E25="HC","C087",OCD!E25="M","C510",OCD!E25="E","C519",OCD!E25="C9","C678", TRUE,"")} -> C087 | E15: {=_xlfn.IFS(OCD!F25="","OFF",OCD!F25="HC","C087",OCD!F25="M","C510",OCD!F25="E","C519",OCD!F25="C9","C678", TRUE,"")} -> C087 | F15: {=_xlfn.IFS(OCD!G25="","OFF",OCD!G25="HC","C087",OCD!G25="M","C510",OCD!G25="E","C519",OCD!G25="C9","C678", TRUE,"")} -> C087 | G15: {=_xlfn.IFS(OCD!H25="","OFF",OCD!H25="HC","C087",OCD!H25="M","C510",OCD!H25="E","C519",OCD!H25="C9","C678", TRUE,"")} -> C087 | H15: {=_xlfn.IFS(OCD!I25="","OFF",OCD!I25="HC","C087",OCD!I25="M","C510",OCD!I25="E","C519",OCD!I25="C9","C678", TRUE,"")} -> C087 | I15: {=_xlfn.IFS(OCD!J25="","OFF",OCD!J25="HC","C087",OCD!J25="M","C510",OCD!J25="E","C519",OCD!J25="C9","C678", TRUE,"")} -> C519 | J15: {=_xlfn.IFS(OCD!K25="","OFF",OCD!K25="HC","C087",OCD!K25="M","C510",OCD!K25="E","C519",OCD!K25="C9","C678", TRUE,"")} -> OFF | ... AG15: {=_xlfn.IFS(OCD!AH25="","OFF",OCD!AH25="HC","C087",OCD!AH25="M","C510",OCD!AH25="E","C519",OCD!AH25="C9","C678", TRUE,"")} -> C519
A16: 031844 | B16: Nguyễn Hoàng Huy | C16: {=_xlfn.IFS(OCD!D26="","OFF",OCD!D26="HC","C087",OCD!D26="M","C510",OCD!D26="E","C519",OCD!D26="C9","C678", TRUE,"")} -> OFF | D16: {=_xlfn.IFS(OCD!E26="","OFF",OCD!E26="HC","C087",OCD!E26="M","C510",OCD!E26="E","C519",OCD!E26="C9","C678", TRUE,"")} -> C510 | E16: {=_xlfn.IFS(OCD!F26="","OFF",OCD!F26="HC","C087",OCD!F26="M","C510",OCD!F26="E","C519",OCD!F26="C9","C678", TRUE,"")} -> C510 | F16: {=_xlfn.IFS(OCD!G26="","OFF",OCD!G26="HC","C087",OCD!G26="M","C510",OCD!G26="E","C519",OCD!G26="C9","C678", TRUE,"")} -> C519 | G16: {=_xlfn.IFS(OCD!H26="","OFF",OCD!H26="HC","C087",OCD!H26="M","C510",OCD!H26="E","C519",OCD!H26="C9","C678", TRUE,"")} -> OFF | H16: {=_xlfn.IFS(OCD!I26="","OFF",OCD!I26="HC","C087",OCD!I26="M","C510",OCD!I26="E","C519",OCD!I26="C9","C678", TRUE,"")} -> C510 | I16: {=_xlfn.IFS(OCD!J26="","OFF",OCD!J26="HC","C087",OCD!J26="M","C510",OCD!J26="E","C519",OCD!J26="C9","C678", TRUE,"")} -> C519 | J16: {=_xlfn.IFS(OCD!K26="","OFF",OCD!K26="HC","C087",OCD!K26="M","C510",OCD!K26="E","C519",OCD!K26="C9","C678", TRUE,"")} -> OFF | ... AG16: {=_xlfn.IFS(OCD!AH26="","OFF",OCD!AH26="HC","C087",OCD!AH26="M","C510",OCD!AH26="E","C519",OCD!AH26="C9","C678", TRUE,"")} -> OFF
A17: 031843 | B17: Lương Trung Hiếu | C17: {=_xlfn.IFS(OCD!D27="","OFF",OCD!D27="HC","C087",OCD!D27="M","C510",OCD!D27="E","C519",OCD!D27="C9","C678", TRUE,"")} -> C519 | D17: {=_xlfn.IFS(OCD!E27="","OFF",OCD!E27="HC","C087",OCD!E27="M","C510",OCD!E27="E","C519",OCD!E27="C9","C678", TRUE,"")} -> OFF | E17: {=_xlfn.IFS(OCD!F27="","OFF",OCD!F27="HC","C087",OCD!F27="M","C510",OCD!F27="E","C519",OCD!F27="C9","C678", TRUE,"")} -> C519 | F17: {=_xlfn.IFS(OCD!G27="","OFF",OCD!G27="HC","C087",OCD!G27="M","C510",OCD!G27="E","C519",OCD!G27="C9","C678", TRUE,"")} -> OFF | G17: {=_xlfn.IFS(OCD!H27="","OFF",OCD!H27="HC","C087",OCD!H27="M","C510",OCD!H27="E","C519",OCD!H27="C9","C678", TRUE,"")} -> C510 | H17: {=_xlfn.IFS(OCD!I27="","OFF",OCD!I27="HC","C087",OCD!I27="M","C510",OCD!I27="E","C519",OCD!I27="C9","C678", TRUE,"")} -> OFF | I17: {=_xlfn.IFS(OCD!J27="","OFF",OCD!J27="HC","C087",OCD!J27="M","C510",OCD!J27="E","C519",OCD!J27="C9","C678", TRUE,"")} -> OFF | J17: {=_xlfn.IFS(OCD!K27="","OFF",OCD!K27="HC","C087",OCD!K27="M","C510",OCD!K27="E","C519",OCD!K27="C9","C678", TRUE,"")} -> OFF | ... AG17: {=_xlfn.IFS(OCD!AH27="","OFF",OCD!AH27="HC","C087",OCD!AH27="M","C510",OCD!AH27="E","C519",OCD!AH27="C9","C678", TRUE,"")} -> OFF
A18: 031846 | B18: Nguyễn Phúc Thịnh | C18: {=_xlfn.IFS(OCD!D28="","OFF",OCD!D28="HC","C087",OCD!D28="M","C510",OCD!D28="E","C519",OCD!D28="C9","C678", TRUE,"")} -> OFF | D18: {=_xlfn.IFS(OCD!E28="","OFF",OCD!E28="HC","C087",OCD!E28="M","C510",OCD!E28="E","C519",OCD!E28="C9","C678", TRUE,"")} -> OFF | E18: {=_xlfn.IFS(OCD!F28="","OFF",OCD!F28="HC","C087",OCD!F28="M","C510",OCD!F28="E","C519",OCD!F28="C9","C678", TRUE,"")} -> OFF | F18: {=_xlfn.IFS(OCD!G28="","OFF",OCD!G28="HC","C087",OCD!G28="M","C510",OCD!G28="E","C519",OCD!G28="C9","C678", TRUE,"")} -> C510 | G18: {=_xlfn.IFS(OCD!H28="","OFF",OCD!H28="HC","C087",OCD!H28="M","C510",OCD!H28="E","C519",OCD!H28="C9","C678", TRUE,"")} -> C519 | H18: {=_xlfn.IFS(OCD!I28="","OFF",OCD!I28="HC","C087",OCD!I28="M","C510",OCD!I28="E","C519",OCD!I28="C9","C678", TRUE,"")} -> C519 | I18: {=_xlfn.IFS(OCD!J28="","OFF",OCD!J28="HC","C087",OCD!J28="M","C510",OCD!J28="E","C519",OCD!J28="C9","C678", TRUE,"")} -> OFF | J18: {=_xlfn.IFS(OCD!K28="","OFF",OCD!K28="HC","C087",OCD!K28="M","C510",OCD!K28="E","C519",OCD!K28="C9","C678", TRUE,"")} -> C510 | ... AG18: {=_xlfn.IFS(OCD!AH28="","OFF",OCD!AH28="HC","C087",OCD!AH28="M","C510",OCD!AH28="E","C519",OCD!AH28="C9","C678", TRUE,"")} -> C519
A19: 031847 | B19: Hoàng Bảo Ngọc | C19: {=_xlfn.IFS(OCD!D29="","OFF",OCD!D29="HC","C087",OCD!D29="M","C510",OCD!D29="E","C519",OCD!D29="C9","C678", TRUE,"")} -> C510 | D19: {=_xlfn.IFS(OCD!E29="","OFF",OCD!E29="HC","C087",OCD!E29="M","C510",OCD!E29="E","C519",OCD!E29="C9","C678", TRUE,"")} -> C519 | E19: {=_xlfn.IFS(OCD!F29="","OFF",OCD!F29="HC","C087",OCD!F29="M","C510",OCD!F29="E","C519",OCD!F29="C9","C678", TRUE,"")} -> OFF | F19: {=_xlfn.IFS(OCD!G29="","OFF",OCD!G29="HC","C087",OCD!G29="M","C510",OCD!G29="E","C519",OCD!G29="C9","C678", TRUE,"")} -> C087 | G19: {=_xlfn.IFS(OCD!H29="","OFF",OCD!H29="HC","C087",OCD!H29="M","C510",OCD!H29="E","C519",OCD!H29="C9","C678", TRUE,"")} -> OFF | H19: {=_xlfn.IFS(OCD!I29="","OFF",OCD!I29="HC","C087",OCD!I29="M","C510",OCD!I29="E","C519",OCD!I29="C9","C678", TRUE,"")} -> C510 | I19: {=_xlfn.IFS(OCD!J29="","OFF",OCD!J29="HC","C087",OCD!J29="M","C510",OCD!J29="E","C519",OCD!J29="C9","C678", TRUE,"")} -> C510 | J19: {=_xlfn.IFS(OCD!K29="","OFF",OCD!K29="HC","C087",OCD!K29="M","C510",OCD!K29="E","C519",OCD!K29="C9","C678", TRUE,"")} -> C519 | ... AG19: {=_xlfn.IFS(OCD!AH29="","OFF",OCD!AH29="HC","C087",OCD!AH29="M","C510",OCD!AH29="E","C519",OCD!AH29="C9","C678", TRUE,"")} -> C510
A20: 041863 | B20: Lê Ngọc Thành Tài | C20: {=_xlfn.IFS(OCD!D30="","OFF",OCD!D30="HC","C087",OCD!D30="M","C510",OCD!D30="E","C519",OCD!D30="C9","C678", TRUE,"")} -> OFF | D20: {=_xlfn.IFS(OCD!E30="","OFF",OCD!E30="HC","C087",OCD!E30="M","C510",OCD!E30="E","C519",OCD!E30="C9","C678", TRUE,"")} -> C087 | E20: {=_xlfn.IFS(OCD!F30="","OFF",OCD!F30="HC","C087",OCD!F30="M","C510",OCD!F30="E","C519",OCD!F30="C9","C678", TRUE,"")} -> C087 | F20: {=_xlfn.IFS(OCD!G30="","OFF",OCD!G30="HC","C087",OCD!G30="M","C510",OCD!G30="E","C519",OCD!G30="C9","C678", TRUE,"")} -> C087 | G20: {=_xlfn.IFS(OCD!H30="","OFF",OCD!H30="HC","C087",OCD!H30="M","C510",OCD!H30="E","C519",OCD!H30="C9","C678", TRUE,"")} -> OFF | H20: {=_xlfn.IFS(OCD!I30="","OFF",OCD!I30="HC","C087",OCD!I30="M","C510",OCD!I30="E","C519",OCD!I30="C9","C678", TRUE,"")} -> C087 | I20: {=_xlfn.IFS(OCD!J30="","OFF",OCD!J30="HC","C087",OCD!J30="M","C510",OCD!J30="E","C519",OCD!J30="C9","C678", TRUE,"")} -> C510 | J20: {=_xlfn.IFS(OCD!K30="","OFF",OCD!K30="HC","C087",OCD!K30="M","C510",OCD!K30="E","C519",OCD!K30="C9","C678", TRUE,"")} -> OFF | ... AG20: {=_xlfn.IFS(OCD!AH30="","OFF",OCD!AH30="HC","C087",OCD!AH30="M","C510",OCD!AH30="E","C519",OCD!AH30="C9","C678", TRUE,"")} -> C519
A21: 041865 | B21: Nguyễn Đức Lộc | C21: {=_xlfn.IFS(OCD!D31="","OFF",OCD!D31="HC","C087",OCD!D31="M","C510",OCD!D31="E","C519",OCD!D31="C9","C678", TRUE,"")} -> OFF | D21: {=_xlfn.IFS(OCD!E31="","OFF",OCD!E31="HC","C087",OCD!E31="M","C510",OCD!E31="E","C519",OCD!E31="C9","C678", TRUE,"")} -> C087 | E21: {=_xlfn.IFS(OCD!F31="","OFF",OCD!F31="HC","C087",OCD!F31="M","C510",OCD!F31="E","C519",OCD!F31="C9","C678", TRUE,"")} -> C087 | F21: {=_xlfn.IFS(OCD!G31="","OFF",OCD!G31="HC","C087",OCD!G31="M","C510",OCD!G31="E","C519",OCD!G31="C9","C678", TRUE,"")} -> C087 | G21: {=_xlfn.IFS(OCD!H31="","OFF",OCD!H31="HC","C087",OCD!H31="M","C510",OCD!H31="E","C519",OCD!H31="C9","C678", TRUE,"")} -> OFF | H21: {=_xlfn.IFS(OCD!I31="","OFF",OCD!I31="HC","C087",OCD!I31="M","C510",OCD!I31="E","C519",OCD!I31="C9","C678", TRUE,"")} -> C087 | I21: {=_xlfn.IFS(OCD!J31="","OFF",OCD!J31="HC","C087",OCD!J31="M","C510",OCD!J31="E","C519",OCD!J31="C9","C678", TRUE,"")} -> C519 | J21: {=_xlfn.IFS(OCD!K31="","OFF",OCD!K31="HC","C087",OCD!K31="M","C510",OCD!K31="E","C519",OCD!K31="C9","C678", TRUE,"")} -> OFF | ... AG21: {=_xlfn.IFS(OCD!AH31="","OFF",OCD!AH31="HC","C087",OCD!AH31="M","C510",OCD!AH31="E","C519",OCD!AH31="C9","C678", TRUE,"")} -> OFF
A22: 041867 | B22: Phan Thành Nghĩa | C22: {=_xlfn.IFS(OCD!D32="","OFF",OCD!D32="HC","C087",OCD!D32="M","C510",OCD!D32="E","C519",OCD!D32="C9","C678", TRUE,"")} -> OFF | D22: {=_xlfn.IFS(OCD!E32="","OFF",OCD!E32="HC","C087",OCD!E32="M","C510",OCD!E32="E","C519",OCD!E32="C9","C678", TRUE,"")} -> C087 | E22: {=_xlfn.IFS(OCD!F32="","OFF",OCD!F32="HC","C087",OCD!F32="M","C510",OCD!F32="E","C519",OCD!F32="C9","C678", TRUE,"")} -> C087 | F22: {=_xlfn.IFS(OCD!G32="","OFF",OCD!G32="HC","C087",OCD!G32="M","C510",OCD!G32="E","C519",OCD!G32="C9","C678", TRUE,"")} -> C087 | G22: {=_xlfn.IFS(OCD!H32="","OFF",OCD!H32="HC","C087",OCD!H32="M","C510",OCD!H32="E","C519",OCD!H32="C9","C678", TRUE,"")} -> OFF | H22: {=_xlfn.IFS(OCD!I32="","OFF",OCD!I32="HC","C087",OCD!I32="M","C510",OCD!I32="E","C519",OCD!I32="C9","C678", TRUE,"")} -> C087 | I22: {=_xlfn.IFS(OCD!J32="","OFF",OCD!J32="HC","C087",OCD!J32="M","C510",OCD!J32="E","C519",OCD!J32="C9","C678", TRUE,"")} -> C678 | J22: {=_xlfn.IFS(OCD!K32="","OFF",OCD!K32="HC","C087",OCD!K32="M","C510",OCD!K32="E","C519",OCD!K32="C9","C678", TRUE,"")} -> C678 | ... AG22: {=_xlfn.IFS(OCD!AH32="","OFF",OCD!AH32="HC","C087",OCD!AH32="M","C510",OCD!AH32="E","C519",OCD!AH32="C9","C678", TRUE,"")} -> C510

Sheet Danh sách ca
A1: Mã ca | B1: Tên ca | C1: Giờ quy định
A2: C496 | B2: 13:30-19:30 | C2: 13:30-19:30
A3: C571 | B3: 10:30-17:30 | C3: 10:30-17:30
A4: C339 | B4: 17:00-07:00 | C4: 17:00-07:00
A5: C572 | B5: 08:30-16:00|12:00-14:30 | C5: 08:30-12:00-14:30-16:00
A6: C341 | B6: 12:30-17:00 | C6: 12:30-17:00
A7: C342 | B7: 13:00-19:00 | C7: 13:00-19:00
A8: C001 | B8: 12:00-20:00 | C8: 12:00-20:00
A9: C343 | B9: 08:00-19:00 | C9: 08:00-19:00
A10: C344 | B10: 08:30-18:00 | C10: 08:30-18:00
A11: C002 | B11: 12:00-21:00 | C11: 12:00-21:00
A12: C345 | B12: 08:00-17:30 | C12: 08:00-17:30
... A255: C633 | B255: 08:00-14:30 | C255: 08:00-14:30
A256: OFF
A257: C515 | B257: 12:00-18:00 | C257: 12:00-18:00
A258: C242 | B258: 21:00-05:30 | C258: 21:00-05:30
A259: C255 | B259: 10:30-19:00 | C259: 10:30-19:00
A260: C260 | B260: 13:30-22:30 | C260: 13:30-22:30
A261: C419 | B261: 01:00-09:00 | C261: 01:00-09:00
A262: C420 | B262: 15:30-23:30 | C262: 15:30-23:30
A263: C263 | B263: 04:00-12:00 | C263: 04:00-12:00
A264: C421 | B264: 00:00-08:00 | C264: 00:00-08:00
A265: C422 | B265: 05:30-14:00 | C265: 05:30-14:00
A266: C423 | B266: 21:30-06:00 | C266: 21:30-06:00
A267: C424 | B267: 13:00-22:00 | C267: 13:00-22:00
A268: C268 | B268: 05:00-19:00 | C268: 05:00-19:00
... A687: C683 | B687: 15:30-23:59 | C687: 15:30-23:59
